Workbook
Name list_Category: Working_Calculations!$P$2:$P$22
Name list_County: Working_Calculations!$R$2:$R$60
Name list_Gender: Working_Calculations!$O$2:$O$6
Name list_Mode: Working_Calculations!$N$2:$N$7
Name list_Month: Working_Calculations!$Q$2:$Q$5
Name Sel_Category: Dashboard!$B$35
Name Sel_County: Dashboard!$B$41
Name Sel_Gender: Dashboard!$B$32
Name Sel_Mode: Dashboard!$B$29
Name Sel_Month: Dashboard!$B$38
Name wk_DeliveryGroup: Working_Calculations!$G$2:$G$2401
Name wk_Flag: Working_Calculations!$I$2:$I$2401
Name wk_Month: Working_Calculations!$C$2:$C$2401
Name wk_RatingGroup: Working_Calculations!$F$2:$F$2401

Sheet Dashboard
E2: Ecommerce Sales & Orders Dashboard
E3: ="Filters > Mode: "&Sel_Mode&" | Gender: "&Sel_Gender&" | Category: "&Sel_Category&" | Month: "&Sel_Month&" | County: "&Sel_County -> Filters > Mode: All | Gender: All | Category: All | Month: All | County: All
E5: Sales & Quantity Trend (weekly) | S5: Gender Contribution
B6: 🛒 TOTAL ORDERS | E6: Trend in the last 13 weeks - quantity (left axis) vs sales amount (right axis) | S6: Overall gender split - share of orders
B7: =Pivot_Calculations!C7 -> 2400
B10: 👕 TOTAL QUANTITY
B11: =Pivot_Calculations!C8 -> 11997
B14: 💰 TOTAL SALES AMOUNT
B15: =Pivot_Calculations!C9 -> 649019.8
B18: ⭐ AVERAGE RATING
B19: =Pivot_Calculations!C10 -> 3.9620833
B22: 📅 AVG DAYS TO DELIVER | E22: Channel Performance by Gender | L22: Monthly Channel Performance | S22: Rating Distribution
B23: =Pivot_Calculations!C11 -> 2.3425 | E23: How our customers like to buy - share of total sales (blue = higher, red = lower) | L23: Sales amount by month and order channel | S23: How happy are our customers? Orders by rating
E25: Channel | G25: Female | H25: Male | I25: Other | J25: Unknown
E26: =Pivot_Calculations!A42 -> App | G26: =Pivot_Calculations!B42 -> 0.18961825 | H26: =Pivot_Calculations!C42 -> 0.12262322 | I26: =Pivot_Calculations!D42 -> 0.010605378 | J26: =Pivot_Calculations!E42 -> 0.030599221
B27: FILTERS (pick from dropdowns)
B28: Order Mode / Channel | E28: =Pivot_Calculations!A43 -> Instagram | G28: =Pivot_Calculations!B43 -> 0.050283982 | H28: =Pivot_Calculations!C43 -> 0.043060782 | I28: =Pivot_Calculations!D43 -> 0.0015320026 | J28: =Pivot_Calculations!E43 -> 0.017794989
B29: All
E30: =Pivot_Calculations!A44 -> Partner App | G30: =Pivot_Calculations!B44 -> 0.06349606 | H30: =Pivot_Calculations!C44 -> 0.04607163 | I30: =Pivot_Calculations!D44 -> 0.0023062471 | J30: =Pivot_Calculations!E44 -> 0.0038927934
B31: Gender
B32: All | E32: =Pivot_Calculations!A45 -> Target.com | G32: =Pivot_Calculations!B45 -> 0.096337893 | H32: =Pivot_Calculations!C45 -> 0.067920116 | I32: =Pivot_Calculations!D45 -> 0.0054979833 | J32: =Pivot_Calculations!E45 -> 0.012933041
B34: Product Category | E34: =Pivot_Calculations!A46 -> Website | G34: =Pivot_Calculations!B46 -> 0.12522099 | H34: =Pivot_Calculations!C46 -> 0.09149274 | I34: =Pivot_Calculations!D46 -> 0.0063042761 | J34: =Pivot_Calculations!E46 -> 0.012408404
B35: All
E36: Cell = channel/gender sales / total filtered sales
B37: Month
B38: All
E39: Product Category Performance | L39: County-wise Quantity Distribution | S39: Delivery Days Analysis
B40: County (State has 1 value) | E40: Which products are popular? Sales by gender, high to low | L40: Where do our customers live? Top 10 counties by quantity | S40: How long we take to ship - orders by days to deliver
B41: All
B44: Set every filter to "All" to reset.
E61: Source: Data sheet (orders table). All numbers recalculate from Pivot_Calculations and respond to the dropdown filters on the left. Data covers one state (California), so the map is a county bar chart. Logic: Working_Calculations, Formula_Guide.

Sheet Pivot_Calculations
A1: PIVOT_CALCULATIONS - formula-driven pivot tables (one per chart)
A2: Every table is a SUMIFS/COUNTIFS "pivot" over the Data table, restricted to Filter Flag = 1 (dashboard dropdowns). Blue = typed labels, black = formulas.
A4: 1. KPI Pivot
A5: Equivalent PivotTable: Values = Count of TX ID, Sum of Quantity, Sum of Amount, Average of Rating, Average of Days to Deliver | Filters = slicers
A6: Metric | B6: All data (spec formula) | C6: Filtered (dashboard)
A7: Total Orders | B7: =COUNTA(orders[TX ID]) -> 2400 | C7: =COUNTIFS(wk_Flag,1) -> 2400
A8: Total Quantity | B8: =SUM(orders[Quantity]) -> 11997 | C8: =SUMIFS(orders[Quantity],wk_Flag,1) -> 11997
A9: Total Sales Amount | B9: =SUM(orders[Amount]) -> 649019.8 | C9: =SUMIFS(orders[Amount],wk_Flag,1) -> 649019.8
A10: Average Rating | B10: =AVERAGE(orders[Rating C]) -> 3.9620833 | C10: =IFERROR(AVERAGEIFS(orders[Rating C],wk_Flag,1),0) -> 3.9620833
A11: Avg Days to Deliver | B11: =AVERAGE(orders[Days to Deliver]) -> 2.3425 | C11: =IFERROR(AVERAGEIFS(orders[Days to Deliver],wk_Flag,1),0) -> 2.3425
A14: 2. Sales Trend Pivot (weekly)
A15: Week # | B15: Week starts | C15: Orders | D15: Quantity | E15: Amount ($)
A16: 1 | B16: =TEXT(_xlfn.MINIFS(orders[Order Date],orders[Weeknum],A16),"d mmm") -> 1 Jan | C16: =COUNTIFS(orders[Weeknum],$A16,wk_Flag,1) -> 101 | D16: =SUMIFS(orders[Quantity],orders[Weeknum],$A16,wk_Flag,1) -> 546 | E16: =SUMIFS(orders[Amount],orders[Weeknum],$A16,wk_Flag,1) -> 32413.3
A17: 2 | B17: =TEXT(_xlfn.MINIFS(orders[Order Date],orders[Weeknum],A17),"d mmm") -> 5 Jan | C17: =COUNTIFS(orders[Weeknum],$A17,wk_Flag,1) -> 155 | D17: =SUMIFS(orders[Quantity],orders[Weeknum],$A17,wk_Flag,1) -> 905 | E17: =SUMIFS(orders[Amount],orders[Weeknum],$A17,wk_Flag,1) -> 49563
A18: 3 | B18: =TEXT(_xlfn.MINIFS(orders[Order Date],orders[Weeknum],A18),"d mmm") -> 12 Jan | C18: =COUNTIFS(orders[Weeknum],$A18,wk_Flag,1) -> 151 | D18: =SUMIFS(orders[Quantity],orders[Weeknum],$A18,wk_Flag,1) -> 796 | E18: =SUMIFS(orders[Amount],orders[Weeknum],$A18,wk_Flag,1) -> 41700.4
A19: 4 | B19: =TEXT(_xlfn.MINIFS(orders[Order Date],orders[Weeknum],A19),"d mmm") -> 19 Jan | C19: =COUNTIFS(orders[Weeknum],$A19,wk_Flag,1) -> 175 | D19: =SUMIFS(orders[Quantity],orders[Weeknum],$A19,wk_Flag,1) -> 913 | E19: =SUMIFS(orders[Amount],orders[Weeknum],$A19,wk_Flag,1) -> 46782.6
A20: 5 | B20: =TEXT(_xlfn.MINIFS(orders[Order Date],orders[Weeknum],A20),"d mmm") -> 26 Jan | C20: =COUNTIFS(orders[Weeknum],$A20,wk_Flag,1) -> 162 | D20: =SUMIFS(orders[Quantity],orders[Weeknum],$A20,wk_Flag,1) -> 844 | E20: =SUMIFS(orders[Amount],orders[Weeknum],$A20,wk_Flag,1) -> 42676.1
A21: 6 | B21: =TEXT(_xlfn.MINIFS(orders[Order Date],orders[Weeknum],A21),"d mmm") -> 2 Feb | C21: =COUNTIFS(orders[Weeknum],$A21,wk_Flag,1) -> 240 | D21: =SUMIFS(orders[Quantity],orders[Weeknum],$A21,wk_Flag,1) -> 1202 | E21: =SUMIFS(orders[Amount],orders[Weeknum],$A21,wk_Flag,1) -> 62910.7
A22: 7 | B22: =TEXT(_xlfn.MINIFS(orders[Order Date],orders[Weeknum],A22),"d mmm") -> 9 Feb | C22: =COUNTIFS(orders[Weeknum],$A22,wk_Flag,1) -> 191 | D22: =SUMIFS(orders[Quantity],orders[Weeknum],$A22,wk_Flag,1) -> 935 | E22: =SUMIFS(orders[Amount],orders[Weeknum],$A22,wk_Flag,1) -> 50332.2
A23: 8 | B23: =TEXT(_xlfn.MINIFS(orders[Order Date],orders[Weeknum],A23),"d mmm") -> 16 Feb | C23: =COUNTIFS(orders[Weeknum],$A23,wk_Flag,1) -> 236 | D23: =SUMIFS(orders[Quantity],orders[Weeknum],$A23,wk_Flag,1) -> 1128 | E23: =SUMIFS(orders[Amount],orders[Weeknum],$A23,wk_Flag,1) -> 58760.6
A24: 9 | B24: =TEXT(_xlfn.MINIFS(orders[Order Date],orders[Weeknum],A24),"d mmm") -> 23 Feb | C24: =COUNTIFS(orders[Weeknum],$A24,wk_Flag,1) -> 202 | D24: =SUMIFS(orders[Quantity],orders[Weeknum],$A24,wk_Flag,1) -> 1007 | E24: =SUMIFS(orders[Amount],orders[Weeknum],$A24,wk_Flag,1) -> 52017.3
A25: 10 | B25: =TEXT(_xlfn.MINIFS(orders[Order Date],orders[Weeknum],A25),"d mmm") -> 2 Mar | C25: =COUNTIFS(orders[Weeknum],$A25,wk_Flag,1) -> 214 | D25: =SUMIFS(orders[Quantity],orders[Weeknum],$A25,wk_Flag,1) -> 1128 | E25: =SUMIFS(orders[Amount],orders[Weeknum],$A25,wk_Flag,1) -> 64915.7
A26: 11 | B26: =TEXT(_xlfn.MINIFS(orders[Order Date],orders[Weeknum],A26),"d mmm") -> 9 Mar | C26: =COUNTIFS(orders[Weeknum],$A26,wk_Flag,1) -> 189 | D26: =SUMIFS(orders[Quantity],orders[Weeknum],$A26,wk_Flag,1) -> 861 | E26: =SUMIFS(orders[Amount],orders[Weeknum],$A26,wk_Flag,1) -> 45943.8
A27: 12 | B27: =TEXT(_xlfn.MINIFS(orders[Order Date],orders[Weeknum],A27),"d mmm") -> 16 Mar | C27: =COUNTIFS(orders[Weeknum],$A27,wk_Flag,1) -> 200 | D27: =SUMIFS(orders[Quantity],orders[Weeknum],$A27,wk_Flag,1) -> 944 | E27: =SUMIFS(orders[Amount],orders[Weeknum],$A27,wk_Flag,1) -> 55077.9
A28: 13 | B28: =TEXT(_xlfn.MINIFS(orders[Order Date],orders[Weeknum],A28),"d mmm") -> 23 Mar | C28: =COUNTIFS(orders[Weeknum],$A28,wk_Flag,1) -> 184 | D28: =SUMIFS(orders[Quantity],orders[Weeknum],$A28,wk_Flag,1) -> 788 | E28: =SUMIFS(orders[Amount],orders[Weeknum],$A28,wk_Flag,1) -> 45926.2
A31: 3. Channel vs Gender Pivot
A32: Equivalent PivotTable: Rows = Order Mode | Columns = Gender Value | Values = Sum of Amount (second block: % of grand total)
A33: Sales ($) | B33: Female | C33: Male | D33: Other | E33: Unknown | F33: Total
A34: App | B34: =SUMIFS(orders[Amount],orders[Order Mode],$A34,orders[Gender Value],B$33,wk_Flag,1) -> 123066 | C34: =SUMIFS(orders[Amount],orders[Order Mode],$A34,orders[Gender Value],C$33,wk_Flag,1) -> 79584.9 | D34: =SUMIFS(orders[Amount],orders[Order Mode],$A34,orders[Gender Value],D$33,wk_Flag,1) -> 6883.1 | E34: =SUMIFS(orders[Amount],orders[Order Mode],$A34,orders[Gender Value],E$33,wk_Flag,1) -> 19859.5 | F34: =SUM(B34:E34) -> 229393.5
A35: Instagram | B35: =SUMIFS(orders[Amount],orders[Order Mode],$A35,orders[Gender Value],B$33,wk_Flag,1) -> 32635.3 | C35: =SUMIFS(orders[Amount],orders[Order Mode],$A35,orders[Gender Value],C$33,wk_Flag,1) -> 27947.3 | D35: =SUMIFS(orders[Amount],orders[Order Mode],$A35,orders[Gender Value],D$33,wk_Flag,1) -> 994.3 | E35: =SUMIFS(orders[Amount],orders[Order Mode],$A35,orders[Gender Value],E$33,wk_Flag,1) -> 11549.3 | F35: =SUM(B35:E35) -> 73126.2
A36: Partner App | B36: =SUMIFS(orders[Amount],orders[Order Mode],$A36,orders[Gender Value],B$33,wk_Flag,1) -> 41210.2 | C36: =SUMIFS(orders[Amount],orders[Order Mode],$A36,orders[Gender Value],C$33,wk_Flag,1) -> 29901.4 | D36: =SUMIFS(orders[Amount],orders[Order Mode],$A36,orders[Gender Value],D$33,wk_Flag,1) -> 1496.8 | E36: =SUMIFS(orders[Amount],orders[Order Mode],$A36,orders[Gender Value],E$33,wk_Flag,1) -> 2526.5 | F36: =SUM(B36:E36) -> 75134.9
A37: Target.com | B37: =SUMIFS(orders[Amount],orders[Order Mode],$A37,orders[Gender Value],B$33,wk_Flag,1) -> 62525.2 | C37: =SUMIFS(orders[Amount],orders[Order Mode],$A37,orders[Gender Value],C$33,wk_Flag,1) -> 44081.5 | D37: =SUMIFS(orders[Amount],orders[Order Mode],$A37,orders[Gender Value],D$33,wk_Flag,1) -> 3568.3 | E37: =SUMIFS(orders[Amount],orders[Order Mode],$A37,orders[Gender Value],E$33,wk_Flag,1) -> 8393.8 | F37: =SUM(B37:E37) -> 118568.8
A38: Website | B38: =SUMIFS(orders[Amount],orders[Order Mode],$A38,orders[Gender Value],B$33,wk_Flag,1) -> 81270.9 | C38: =SUMIFS(orders[Amount],orders[Order Mode],$A38,orders[Gender Value],C$33,wk_Flag,1) -> 59380.6 | D38: =SUMIFS(orders[Amount],orders[Order Mode],$A38,orders[Gender Value],D$33,wk_Flag,1) -> 4091.6 | E38: =SUMIFS(orders[Amount],orders[Order Mode],$A38,orders[Gender Value],E$33,wk_Flag,1) -> 8053.3 | F38: =SUM(B38:E38) -> 152796.4
A39: Total | B39: =SUM(B34:B38) -> 340707.6 | C39: =SUM(C34:C38) -> 240895.7 | D39: =SUM(D34:D38) -> 17034.1 | E39: =SUM(E34:E38) -> 50382.4 | F39: =SUM(F34:F38) -> 649019.8
A41: % of total sales | B41: Female | C41: Male | D41: Other | E41: Unknown | F41: Total
A42: =A34 -> App | B42: =IFERROR(B34/$F$39,0) -> 0.18961825 | C42: =IFERROR(C34/$F$39,0) -> 0.12262322 | D42: =IFERROR(D34/$F$39,0) -> 0.010605378 | E42: =IFERROR(E34/$F$39,0) -> 0.030599221 | F42: =IFERROR(F34/$F$39,0) -> 0.35344607
A43: =A35 -> Instagram | B43: =IFERROR(B35/$F$39,0) -> 0.050283982 | C43: =IFERROR(C35/$F$39,0) -> 0.043060782 | D43: =IFERROR(D35/$F$39,0) -> 0.0015320026 | E43: =IFERROR(E35/$F$39,0) -> 0.017794989 | F43: =IFERROR(F35/$F$39,0) -> 0.11267176
A44: =A36 -> Partner App | B44: =IFERROR(B36/$F$39,0) -> 0.06349606 | C44: =IFERROR(C36/$F$39,0) -> 0.04607163 | D44: =IFERROR(D36/$F$39,0) -> 0.0023062471 | E44: =IFERROR(E36/$F$39,0) -> 0.0038927934 | F44: =IFERROR(F36/$F$39,0) -> 0.11576673
A45: =A37 -> Target.com | B45: =IFERROR(B37/$F$39,0) -> 0.096337893 | C45: =IFERROR(C37/$F$39,0) -> 0.067920116 | D45: =IFERROR(D37/$F$39,0) -> 0.0054979833 | E45: =IFERROR(E37/$F$39,0) -> 0.012933041 | F45: =IFERROR(F37/$F$39,0) -> 0.18268903
A46: =A38 -> Website | B46: =IFERROR(B38/$F$39,0) -> 0.12522099 | C46: =IFERROR(C38/$F$39,0) -> 0.09149274 | D46: =IFERROR(D38/$F$39,0) -> 0.0063042761 | E46: =IFERROR(E38/$F$39,0) -> 0.012408404 | F46: =IFERROR(F38/$F$39,0) -> 0.23542641
...

Sheet Working_Calculations
A1: TX ID | B1: Month Num | C1: Month | D1: Gender | E1: Days to Deliver | F1: Rating Group | G1: Delivery Group | H1: Amount Check | I1: Filter Flag | K1: HOW THIS SHEET WORKS | N1: List: Mode | O1: List: Gender | P1: List: Category | Q1: List: Month | R1: List: County
A2: =Data!A2 -> TX500001 | B2: =MONTH(Data!F2) -> 1 | C2: =TEXT(Data!F2,"mmm") -> Jan | D2: =Data!O2 -> Unknown | E2: =Data!G2-Data!F2 -> 5 | F2: =IF(Data!J2<=5,Data!J2,IF(Data!J2<=10,"6 TO 10","More than 10")) -> 4 | G2: =IF(E2>=8,"8+",E2) -> 5 | H2: =ROUND(Data!C2*Data!D2-Data!E2,2) -> 0 | I2: =IF(AND(OR(Sel_Mode="All",Data!I2=Sel_Mode),OR(Sel_Gender="All",D2=Sel_Gender),OR(Sel_Category="All",Data!B2=Sel_Category),OR(Sel_Month="All",C2=Sel_Month),OR(Sel_County="All",Data!L2=Sel_County)),1,0) -> 1 | K2: Row n here = row n on the Data sheet (same order, 2,400 rows). | N2: All | O2: All | P2: All | Q2: All | R2: All
A3: =Data!A3 -> TX500002 | B3: =MONTH(Data!F3) -> 1 | C3: =TEXT(Data!F3,"mmm") -> Jan | D3: =Data!O3 -> Male | E3: =Data!G3-Data!F3 -> 2 | F3: =IF(Data!J3<=5,Data!J3,IF(Data!J3<=10,"6 TO 10","More than 10")) -> 4 | G3: =IF(E3>=8,"8+",E3) -> 2 | H3: =ROUND(Data!C3*Data!D3-Data!E3,2) -> 0 | I3: =IF(AND(OR(Sel_Mode="All",Data!I3=Sel_Mode),OR(Sel_Gender="All",D3=Sel_Gender),OR(Sel_Category="All",Data!B3=Sel_Category),OR(Sel_Month="All",C3=Sel_Month),OR(Sel_County="All",Data!L3=Sel_County)),1,0) -> 1 | K3: Month Num / Month: =MONTH(date) and =TEXT(date,"mmm"). | N3: App | O3: Female | P3: Baseball Caps | Q3: Jan | R3: Alameda County
A4: =Data!A4 -> TX500003 | B4: =MONTH(Data!F4) -> 1 | C4: =TEXT(Data!F4,"mmm") -> Jan | D4: =Data!O4 -> Female | E4: =Data!G4-Data!F4 -> 3 | F4: =IF(Data!J4<=5,Data!J4,IF(Data!J4<=10,"6 TO 10","More than 10")) -> 3 | G4: =IF(E4>=8,"8+",E4) -> 3 | H4: =ROUND(Data!C4*Data!D4-Data!E4,2) -> 0 | I4: =IF(AND(OR(Sel_Mode="All",Data!I4=Sel_Mode),OR(Sel_Gender="All",D4=Sel_Gender),OR(Sel_Category="All",Data!B4=Sel_Category),OR(Sel_Month="All",C4=Sel_Month),OR(Sel_County="All",Data!L4=Sel_County)),1,0) -> 1 | K4: Gender: reuses the "Gender Value" column of the Data table (M/F/O/blank -> Male/Female/Other/Unknown). | N4: Instagram | O4: Male | P4: Bikinis | Q4: Feb | R4: Alpine County
A5: =Data!A5 -> TX500004 | B5: =MONTH(Data!F5) -> 1 | C5: =TEXT(Data!F5,"mmm") -> Jan | D5: =Data!O5 -> Female | E5: =Data!G5-Data!F5 -> 1 | F5: =IF(Data!J5<=5,Data!J5,IF(Data!J5<=10,"6 TO 10","More than 10")) -> 4 | G5: =IF(E5>=8,"8+",E5) -> 1 | H5: =ROUND(Data!C5*Data!D5-Data!E5,2) -> 0 | I5: =IF(AND(OR(Sel_Mode="All",Data!I5=Sel_Mode),OR(Sel_Gender="All",D5=Sel_Gender),OR(Sel_Category="All",Data!B5=Sel_Category),OR(Sel_Month="All",C5=Sel_Month),OR(Sel_County="All",Data!L5=Sel_County)),1,0) -> 1 | K5: Days to Deliver: =Ship Date - Order Date. Delivery Group: 8 or more days -> "8+". | N5: Partner App | O5: Other | P5: Casual Dresses | Q5: Mar | R5: Amador County
A6: =Data!A6 -> TX500005 | B6: =MONTH(Data!F6) -> 1 | C6: =TEXT(Data!F6,"mmm") -> Jan | D6: =Data!O6 -> Female | E6: =Data!G6-Data!F6 -> 3 | F6: =IF(Data!J6<=5,Data!J6,IF(Data!J6<=10,"6 TO 10","More than 10")) -> 5 | G6: =IF(E6>=8,"8+",E6) -> 3 | H6: =ROUND(Data!C6*Data!D6-Data!E6,2) -> 0 | I6: =IF(AND(OR(Sel_Mode="All",Data!I6=Sel_Mode),OR(Sel_Gender="All",D6=Sel_Gender),OR(Sel_Category="All",Data!B6=Sel_Category),OR(Sel_Month="All",C6=Sel_Month),OR(Sel_County="All",Data!L6=Sel_County)),1,0) -> 1 | K6: Rating Group: 1-5 stay as-is, 6-10 -> "6 TO 10", above 10 -> "More than 10". | N6: Target.com | O6: Unknown | P6: Crop Tops | R6: Butte County
A7: =Data!A7 -> TX500006 | B7: =MONTH(Data!F7) -> 1 | C7: =TEXT(Data!F7,"mmm") -> Jan | D7: =Data!O7 -> Male | E7: =Data!G7-Data!F7 -> 3 | F7: =IF(Data!J7<=5,Data!J7,IF(Data!J7<=10,"6 TO 10","More than 10")) -> 4 | G7: =IF(E7>=8,"8+",E7) -> 3 | H7: =ROUND(Data!C7*Data!D7-Data!E7,2) -> 0 | I7: =IF(AND(OR(Sel_Mode="All",Data!I7=Sel_Mode),OR(Sel_Gender="All",D7=Sel_Gender),OR(Sel_Category="All",Data!B7=Sel_Category),OR(Sel_Month="All",C7=Sel_Month),OR(Sel_County="All",Data!L7=Sel_County)),1,0) -> 1 | K7: Amount Check: Quantity x Unit Price - Amount (0 = OK). | N7: Website | P7: Graphic Tees | R7: Calaveras County
A8: =Data!A8 -> TX500007 | B8: =MONTH(Data!F8) -> 1 | C8: =TEXT(Data!F8,"mmm") -> Jan | D8: =Data!O8 -> Female | E8: =Data!G8-Data!F8 -> 1 | F8: =IF(Data!J8<=5,Data!J8,IF(Data!J8<=10,"6 TO 10","More than 10")) -> 4 | G8: =IF(E8>=8,"8+",E8) -> 1 | H8: =ROUND(Data!C8*Data!D8-Data!E8,2) -> 0 | I8: =IF(AND(OR(Sel_Mode="All",Data!I8=Sel_Mode),OR(Sel_Gender="All",D8=Sel_Gender),OR(Sel_Category="All",Data!B8=Sel_Category),OR(Sel_Month="All",C8=Sel_Month),OR(Sel_County="All",Data!L8=Sel_County)),1,0) -> 1 | K8: Filter Flag: 1 if the row passes ALL five dashboard dropdowns, else 0. | P8: Hoodies & Sweatshirts | R8: Colusa County
A9: =Data!A9 -> TX500008 | B9: =MONTH(Data!F9) -> 1 | C9: =TEXT(Data!F9,"mmm") -> Jan | D9: =Data!O9 -> Male | E9: =Data!G9-Data!F9 -> 1 | F9: =IF(Data!J9<=5,Data!J9,IF(Data!J9<=10,"6 TO 10","More than 10")) -> 5 | G9: =IF(E9>=8,"8+",E9) -> 1 | H9: =ROUND(Data!C9*Data!D9-Data!E9,2) -> 0 | I9: =IF(AND(OR(Sel_Mode="All",Data!I9=Sel_Mode),OR(Sel_Gender="All",D9=Sel_Gender),OR(Sel_Category="All",Data!B9=Sel_Category),OR(Sel_Month="All",C9=Sel_Month),OR(Sel_County="All",Data!L9=Sel_County)),1,0) -> 1 | K9: Every Pivot_Calculations formula uses "Filter Flag = 1", which is how the | P9: Jeans | R9: Contra Costa County
A10: =Data!A10 -> TX500009 | B10: =MONTH(Data!F10) -> 1 | C10: =TEXT(Data!F10,"mmm") -> Jan | D10: =Data!O10 -> Female | E10: =Data!G10-Data!F10 -> 1 | F10: =IF(Data!J10<=5,Data!J10,IF(Data!J10<=10,"6 TO 10","More than 10")) -> 4 | G10: =IF(E10>=8,"8+",E10) -> 1 | H10: =ROUND(Data!C10*Data!D10-Data!E10,2) -> 0 | I10: =IF(AND(OR(Sel_Mode="All",Data!I10=Sel_Mode),OR(Sel_Gender="All",D10=Sel_Gender),OR(Sel_Category="All",Data!B10=Sel_Category),OR(Sel_Month="All",C10=Sel_Month),OR(Sel_County="All",Data!L10=Sel_County)),1,0) -> 1 | K10: dropdowns drive every chart and KPI (replacing slicers). | P10: Jewelry | R10: Del Norte County
A11: =Data!A11 -> TX500010 | B11: =MONTH(Data!F11) -> 1 | C11: =TEXT(Data!F11,"mmm") -> Jan | D11: =Data!O11 -> Male | E11: =Data!G11-Data!F11 -> 3 | F11: =IF(Data!J11<=5,Data!J11,IF(Data!J11<=10,"6 TO 10","More than 10")) -> 3 | G11: =IF(E11>=8,"8+",E11) -> 3 | H11: =ROUND(Data!C11*Data!D11-Data!E11,2) -> 0 | I11: =IF(AND(OR(Sel_Mode="All",Data!I11=Sel_Mode),OR(Sel_Gender="All",D11=Sel_Gender),OR(Sel_Category="All",Data!B11=Sel_Category),OR(Sel_Month="All",C11=Sel_Month),OR(Sel_County="All",Data!L11=Sel_County)),1,0) -> 1 | K11: If you append rows to the Data table, copy the formulas here down and extend named ranges (Formulas > Name Manager). | P11: Leggings | R11: El Dorado County
A12: =Data!A12 -> TX500011 | B12: =MONTH(Data!F12) -> 1 | C12: =TEXT(Data!F12,"mmm") -> Jan | D12: =Data!O12 -> Female | E12: =Data!G12-Data!F12 -> 6 | F12: =IF(Data!J12<=5,Data!J12,IF(Data!J12<=10,"6 TO 10","More than 10")) -> 4 | G12: =IF(E12>=8,"8+",E12) -> 6 | H12: =ROUND(Data!C12*Data!D12-Data!E12,2) -> 0 | I12: =IF(AND(OR(Sel_Mode="All",Data!I12=Sel_Mode),OR(Sel_Gender="All",D12=Sel_Gender),OR(Sel_Category="All",Data!B12=Sel_Category),OR(Sel_Month="All",C12=Sel_Month),OR(Sel_County="All",Data!L12=Sel_County)),1,0) -> 1 | P12: Maxi Dresses | R12: Fresno County
A13: =Data!A13 -> TX500012 | B13: =MONTH(Data!F13) -> 1 | C13: =TEXT(Data!F13,"mmm") -> Jan | D13: =Data!O13 -> Female | E13: =Data!G13-Data!F13 -> 2 | F13: =IF(Data!J13<=5,Data!J13,IF(Data!J13<=10,"6 TO 10","More than 10")) -> 3 | G13: =IF(E13>=8,"8+",E13) -> 2 | H13: =ROUND(Data!C13*Data!D13-Data!E13,2) -> 0 | I13: =IF(AND(OR(Sel_Mode="All",Data!I13=Sel_Mode),OR(Sel_Gender="All",D13=Sel_Gender),OR(Sel_Category="All",Data!B13=Sel_Category),OR(Sel_Month="All",C13=Sel_Month),OR(Sel_County="All",Data!L13=Sel_County)),1,0) -> 1 | K13: DATA QUALITY CHECKS | L13: Result | P13: Pajama Sets | R13: Glenn County
A14: =Data!A14 -> TX500013 | B14: =MONTH(Data!F14) -> 1 | C14: =TEXT(Data!F14,"mmm") -> Jan | D14: =Data!O14 -> Female | E14: =Data!G14-Data!F14 -> 4 | F14: =IF(Data!J14<=5,Data!J14,IF(Data!J14<=10,"6 TO 10","More than 10")) -> 4 | G14: =IF(E14>=8,"8+",E14) -> 4 | H14: =ROUND(Data!C14*Data!D14-Data!E14,2) -> 0 | I14: =IF(AND(OR(Sel_Mode="All",Data!I14=Sel_Mode),OR(Sel_Gender="All",D14=Sel_Gender),OR(Sel_Category="All",Data!B14=Sel_Category),OR(Sel_Month="All",C14=Sel_Month),OR(Sel_County="All",Data!L14=Sel_County)),1,0) -> 1 | K14: Rows in Data table | L14: =ROWS(orders[TX ID]) -> 2400 | P14: Sandals | R14: Humboldt County
A15: =Data!A15 -> TX500014 | B15: =MONTH(Data!F15) -> 1 | C15: =TEXT(Data!F15,"mmm") -> Jan | D15: =Data!O15 -> Male | E15: =Data!G15-Data!F15 -> 7 | F15: =IF(Data!J15<=5,Data!J15,IF(Data!J15<=10,"6 TO 10","More than 10")) -> 4 | G15: =IF(E15>=8,"8+",E15) -> 7 | H15: =ROUND(Data!C15*Data!D15-Data!E15,2) -> 0 | I15: =IF(AND(OR(Sel_Mode="All",Data!I15=Sel_Mode),OR(Sel_Gender="All",D15=Sel_Gender),OR(Sel_Category="All",Data!B15=Sel_Category),OR(Sel_Month="All",C15=Sel_Month),OR(Sel_County="All",Data!L15=Sel_County)),1,0) -> 1 | K15: Blank gender codes (shown as "Unknown") | L15: =COUNTBLANK(orders[Customer Gender]) -> 135 | P15: Shorts | R15: Imperial County
A16: =Data!A16 -> TX500015 | B16: =MONTH(Data!F16) -> 1 | C16: =TEXT(Data!F16,"mmm") -> Jan | D16: =Data!O16 -> Male | E16: =Data!G16-Data!F16 -> 3 | F16: =IF(Data!J16<=5,Data!J16,IF(Data!J16<=10,"6 TO 10","More than 10")) -> 4 | G16: =IF(E16>=8,"8+",E16) -> 3 | H16: =ROUND(Data!C16*Data!D16-Data!E16,2) -> 0 | I16: =IF(AND(OR(Sel_Mode="All",Data!I16=Sel_Mode),OR(Sel_Gender="All",D16=Sel_Gender),OR(Sel_Category="All",Data!B16=Sel_Category),OR(Sel_Month="All",C16=Sel_Month),OR(Sel_County="All",Data!L16=Sel_County)),1,0) -> 1 | K16: Duplicate TX IDs | L16: =SUMPRODUCT(--(COUNTIF(orders[TX ID],orders[TX ID])>1)) -> 0 | P16: Sneakers | R16: Inyo County
A17: =Data!A17 -> TX500016 | B17: =MONTH(Data!F17) -> 1 | C17: =TEXT(Data!F17,"mmm") -> Jan | D17: =Data!O17 -> Male | E17: =Data!G17-Data!F17 -> 1 | F17: =IF(Data!J17<=5,Data!J17,IF(Data!J17<=10,"6 TO 10","More than 10")) -> 5 | G17: =IF(E17>=8,"8+",E17) -> 1 | H17: =ROUND(Data!C17*Data!D17-Data!E17,2) -> 0 | I17: =IF(AND(OR(Sel_Mode="All",Data!I17=Sel_Mode),OR(Sel_Gender="All",D17=Sel_Gender),OR(Sel_Category="All",Data!B17=Sel_Category),OR(Sel_Month="All",C17=Sel_Month),OR(Sel_County="All",Data!L17=Sel_County)),1,0) -> 1 | K17: Negative delivery days | L17: =COUNTIF($E$2:$E$2401,"<0") -> 0 | P17: Sundresses | R17: Kern County
A18: =Data!A18 -> TX500017 | B18: =MONTH(Data!F18) -> 1 | C18: =TEXT(Data!F18,"mmm") -> Jan | D18: =Data!O18 -> Female | E18: =Data!G18-Data!F18 -> 1 | F18: =IF(Data!J18<=5,Data!J18,IF(Data!J18<=10,"6 TO 10","More than 10")) -> 3 | G18: =IF(E18>=8,"8+",E18) -> 1 | H18: =ROUND(Data!C18*Data!D18-Data!E18,2) -> 0 | I18: =IF(AND(OR(Sel_Mode="All",Data!I18=Sel_Mode),OR(Sel_Gender="All",D18=Sel_Gender),OR(Sel_Category="All",Data!B18=Sel_Category),OR(Sel_Month="All",C18=Sel_Month),OR(Sel_County="All",Data!L18=Sel_County)),1,0) -> 1 | K18: Amount <> Quantity x Unit Price | L18: =COUNTIF($H$2:$H$2401,"<>0") -> 0 | P18: Sunglasses | R18: Kings County
A19: =Data!A19 -> TX500018 | B19: =MONTH(Data!F19) -> 1 | C19: =TEXT(Data!F19,"mmm") -> Jan | D19: =Data!O19 -> Female | E19: =Data!G19-Data!F19 -> 3 | F19: =IF(Data!J19<=5,Data!J19,IF(Data!J19<=10,"6 TO 10","More than 10")) -> 4 | G19: =IF(E19>=8,"8+",E19) -> 3 | H19: =ROUND(Data!C19*Data!D19-Data!E19,2) -> 0 | I19: =IF(AND(OR(Sel_Mode="All",Data!I19=Sel_Mode),OR(Sel_Gender="All",D19=Sel_Gender),OR(Sel_Category="All",Data!B19=Sel_Category),OR(Sel_Month="All",C19=Sel_Month),OR(Sel_County="All",Data!L19=Sel_County)),1,0) -> 1 | K19: Ratings outside 1-5 | L19: =COUNTIF(orders[Rating C],"<1")+COUNTIF(orders[Rating C],">5") -> 0 | P19: T-Shirts | R19: Lake County
A20: =Data!A20 -> TX500019 | B20: =MONTH(Data!F20) -> 1 | C20: =TEXT(Data!F20,"mmm") -> Jan | D20: =Data!O20 -> Female | E20: =Data!G20-Data!F20 -> 3 | F20: =IF(Data!J20<=5,Data!J20,IF(Data!J20<=10,"6 TO 10","More than 10")) -> 1 | G20: =IF(E20>=8,"8+",E20) -> 3 | H20: =ROUND(Data!C20*Data!D20-Data!E20,2) -> 0 | I20: =IF(AND(OR(Sel_Mode="All",Data!I20=Sel_Mode),OR(Sel_Gender="All",D20=Sel_Gender),OR(Sel_Category="All",Data!B20=Sel_Category),OR(Sel_Month="All",C20=Sel_Month),OR(Sel_County="All",Data!L20=Sel_County)),1,0) -> 1 | K20: Days here <> Days on Data sheet | L20: =SUMPRODUCT(--($E$2:$E$2401<>orders[Days to Deliver])) -> 0 | P20: Tank Tops | R20: Lassen County
A21: =Data!A21 -> TX500020 | B21: =MONTH(Data!F21) -> 1 | C21: =TEXT(Data!F21,"mmm") -> Jan | D21: =Data!O21 -> Female | E21: =Data!G21-Data!F21 -> 1 | F21: =IF(Data!J21<=5,Data!J21,IF(Data!J21<=10,"6 TO 10","More than 10")) -> 5 | G21: =IF(E21>=8,"8+",E21) -> 1 | H21: =ROUND(Data!C21*Data!D21-Data!E21,2) -> 0 | I21: =IF(AND(OR(Sel_Mode="All",Data!I21=Sel_Mode),OR(Sel_Gender="All",D21=Sel_Gender),OR(Sel_Category="All",Data!B21=Sel_Category),OR(Sel_Month="All",C21=Sel_Month),OR(Sel_County="All",Data!L21=Sel_County)),1,0) -> 1 | P21: Tote Bags | R21: Los Angeles County
A22: =Data!A22 -> TX500021 | B22: =MONTH(Data!F22) -> 1 | C22: =TEXT(Data!F22,"mmm") -> Jan | D22: =Data!O22 -> Female | E22: =Data!G22-Data!F22 -> 3 | F22: =IF(Data!J22<=5,Data!J22,IF(Data!J22<=10,"6 TO 10","More than 10")) -> 4 | G22: =IF(E22>=8,"8+",E22) -> 3 | H22: =ROUND(Data!C22*Data!D22-Data!E22,2) -> 0 | I22: =IF(AND(OR(Sel_Mode="All",Data!I22=Sel_Mode),OR(Sel_Gender="All",D22=Sel_Gender),OR(Sel_Category="All",Data!B22=Sel_Category),OR(Sel_Month="All",C22=Sel_Month),OR(Sel_County="All",Data!L22=Sel_County)),1,0) -> 1 | P22: Workout Tops | R22: Madera County
A23: =Data!A23 -> TX500022 | B23: =MONTH(Data!F23) -> 1 | C23: =TEXT(Data!F23,"mmm") -> Jan | D23: =Data!O23 -> Female | E23: =Data!G23-Data!F23 -> 1 | F23: =IF(Data!J23<=5,Data!J23,IF(Data!J23<=10,"6 TO 10","More than 10")) -> 3 | G23: =IF(E23>=8,"8+",E23) -> 1 | H23: =ROUND(Data!C23*Data!D23-Data!E23,2) -> 0 | I23: =IF(AND(OR(Sel_Mode="All",Data!I23=Sel_Mode),OR(Sel_Gender="All",D23=Sel_Gender),OR(Sel_Category="All",Data!B23=Sel_Category),OR(Sel_Month="All",C23=Sel_Month),OR(Sel_County="All",Data!L23=Sel_County)),1,0) -> 1 | R23: Marin County
A24: =Data!A24 -> TX500023 | B24: =MONTH(Data!F24) -> 1 | C24: =TEXT(Data!F24,"mmm") -> Jan | D24: =Data!O24 -> Male | E24: =Data!G24-Data!F24 -> 1 | F24: =IF(Data!J24<=5,Data!J24,IF(Data!J24<=10,"6 TO 10","More than 10")) -> 5 | G24: =IF(E24>=8,"8+",E24) -> 1 | H24: =ROUND(Data!C24*Data!D24-Data!E24,2) -> 0 | I24: =IF(AND(OR(Sel_Mode="All",Data!I24=Sel_Mode),OR(Sel_Gender="All",D24=Sel_Gender),OR(Sel_Category="All",Data!B24=Sel_Category),OR(Sel_Month="All",C24=Sel_Month),OR(Sel_County="All",Data!L24=Sel_County)),1,0) -> 1 | R24: Mariposa County
A25: =Data!A25 -> TX500024 | B25: =MONTH(Data!F25) -> 1 | C25: =TEXT(Data!F25,"mmm") -> Jan | D25: =Data!O25 -> Female | E25: =Data!G25-Data!F25 -> 1 | F25: =IF(Data!J25<=5,Data!J25,IF(Data!J25<=10,"6 TO 10","More than 10")) -> 4 | G25: =IF(E25>=8,"8+",E25) -> 1 | H25: =ROUND(Data!C25*Data!D25-Data!E25,2) -> 0 | I25: =IF(AND(OR(Sel_Mode="All",Data!I25=Sel_Mode),OR(Sel_Gender="All",D25=Sel_Gender),OR(Sel_Category="All",Data!B25=Sel_Category),OR(Sel_Month="All",C25=Sel_Month),OR(Sel_County="All",Data!L25=Sel_County)),1,0) -> 1 | R25: Mendocino County
A26: =Data!A26 -> TX500025 | B26: =MONTH(Data!F26) -> 1 | C26: =TEXT(Data!F26,"mmm") -> Jan | D26: =Data!O26 -> Female | E26: =Data!G26-Data!F26 -> 1 | F26: =IF(Data!J26<=5,Data!J26,IF(Data!J26<=10,"6 TO 10","More than 10")) -> 4 | G26: =IF(E26>=8,"8+",E26) -> 1 | H26: =ROUND(Data!C26*Data!D26-Data!E26,2) -> 0 | I26: =IF(AND(OR(Sel_Mode="All",Data!I26=Sel_Mode),OR(Sel_Gender="All",D26=Sel_Gender),OR(Sel_Category="All",Data!B26=Sel_Category),OR(Sel_Month="All",C26=Sel_Month),OR(Sel_County="All",Data!L26=Sel_County)),1,0) -> 1 | R26: Merced County
A27: =Data!A27 -> TX500026 | B27: =MONTH(Data!F27) -> 1 | C27: =TEXT(Data!F27,"mmm") -> Jan | D27: =Data!O27 -> Female | E27: =Data!G27-Data!F27 -> 1 | F27: =IF(Data!J27<=5,Data!J27,IF(Data!J27<=10,"6 TO 10","More than 10")) -> 4 | G27: =IF(E27>=8,"8+",E27) -> 1 | H27: =ROUND(Data!C27*Data!D27-Data!E27,2) -> 0 | I27: =IF(AND(OR(Sel_Mode="All",Data!I27=Sel_Mode),OR(Sel_Gender="All",D27=Sel_Gender),OR(Sel_Category="All",Data!B27=Sel_Category),OR(Sel_Month="All",C27=Sel_Month),OR(Sel_County="All",Data!L27=Sel_County)),1,0) -> 1 | R27: Modoc County
A28: =Data!A28 -> TX500027 | B28: =MONTH(Data!F28) -> 1 | C28: =TEXT(Data!F28,"mmm") -> Jan | D28: =Data!O28 -> Male | E28: =Data!G28-Data!F28 -> 3 | F28: =IF(Data!J28<=5,Data!J28,IF(Data!J28<=10,"6 TO 10","More than 10")) -> 4 | G28: =IF(E28>=8,"8+",E28) -> 3 | H28: =ROUND(Data!C28*Data!D28-Data!E28,2) -> 0 | I28: =IF(AND(OR(Sel_Mode="All",Data!I28=Sel_Mode),OR(Sel_Gender="All",D28=Sel_Gender),OR(Sel_Category="All",Data!B28=Sel_Category),OR(Sel_Month="All",C28=Sel_Month),OR(Sel_County="All",Data!L28=Sel_County)),1,0) -> 1 | R28: Mono County
A29: =Data!A29 -> TX500028 | B29: =MONTH(Data!F29) -> 1 | C29: =TEXT(Data!F29,"mmm") -> Jan | D29: =Data!O29 -> Unknown | E29: =Data!G29-Data!F29 -> 2 | F29: =IF(Data!J29<=5,Data!J29,IF(Data!J29<=10,"6 TO 10","More than 10")) -> 5 | G29: =IF(E29>=8,"8+",E29) -> 2 | H29: =ROUND(Data!C29*Data!D29-Data!E29,2) -> 0 | I29: =IF(AND(OR(Sel_Mode="All",Data!I29=Sel_Mode),OR(Sel_Gender="All",D29=Sel_Gender),OR(Sel_Category="All",Data!B29=Sel_Category),OR(Sel_Month="All",C29=Sel_Month),OR(Sel_County="All",Data!L29=Sel_County)),1,0) -> 1 | R29: Monterey County
A30: =Data!A30 -> TX500029 | B30: =MONTH(Data!F30) -> 1 | C30: =TEXT(Data!F30,"mmm") -> Jan | D30: =Data!O30 -> Unknown | E30: =Data!G30-Data!F30 -> 6 | F30: =IF(Data!J30<=5,Data!J30,IF(Data!J30<=10,"6 TO 10","More than 10")) -> 5 | G30: =IF(E30>=8,"8+",E30) -> 6 | H30: =ROUND(Data!C30*Data!D30-Data!E30,2) -> 0 | I30: =IF(AND(OR(Sel_Mode="All",Data!I30=Sel_Mode),OR(Sel_Gender="All",D30=Sel_Gender),OR(Sel_Category="All",Data!B30=Sel_Category),OR(Sel_Month="All",C30=Sel_Month),OR(Sel_County="All",Data!L30=Sel_County)),1,0) -> 1 | R30: Napa County
A31: =Data!A31 -> TX500030 | B31: =MONTH(Data!F31) -> 1 | C31: =TEXT(Data!F31,"mmm") -> Jan | D31: =Data!O31 -> Female | E31: =Data!G31-Data!F31 -> 4 | F31: =IF(Data!J31<=5,Data!J31,IF(Data!J31<=10,"6 TO 10","More than 10")) -> 4 | G31: =IF(E31>=8,"8+",E31) -> 4 | H31: =ROUND(Data!C31*Data!D31-Data!E31,2) -> 0 | I31: =IF(AND(OR(Sel_Mode="All",Data!I31=Sel_Mode),OR(Sel_Gender="All",D31=Sel_Gender),OR(Sel_Category="All",Data!B31=Sel_Category),OR(Sel_Month="All",C31=Sel_Month),OR(Sel_County="All",Data!L31=Sel_County)),1,0) -> 1 | R31: Nevada County
A32: =Data!A32 -> TX500031 | B32: =MONTH(Data!F32) -> 1 | C32: =TEXT(Data!F32,"mmm") -> Jan | D32: =Data!O32 -> Male | E32: =Data!G32-Data!F32 -> 4 | F32: =IF(Data!J32<=5,Data!J32,IF(Data!J32<=10,"6 TO 10","More than 10")) -> 5 | G32: =IF(E32>=8,"8+",E32) -> 4 | H32: =ROUND(Data!C32*Data!D32-Data!E32,2) -> 0 | I32: =IF(AND(OR(Sel_Mode="All",Data!I32=Sel_Mode),OR(Sel_Gender="All",D32=Sel_Gender),OR(Sel_Category="All",Data!B32=Sel_Category),OR(Sel_Month="All",C32=Sel_Month),OR(Sel_County="All",Data!L32=Sel_County)),1,0) -> 1 | R32: Orange County
A33: =Data!A33 -> TX500032 | B33: =MONTH(Data!F33) -> 1 | C33: =TEXT(Data!F33,"mmm") -> Jan | D33: =Data!O33 -> Male | E33: =Data!G33-Data!F33 -> 3 | F33: =IF(Data!J33<=5,Data!J33,IF(Data!J33<=10,"6 TO 10","More than 10")) -> 4 | G33: =IF(E33>=8,"8+",E33) -> 3 | H33: =ROUND(Data!C33*Data!D33-Data!E33,2) -> 0 | I33: =IF(AND(OR(Sel_Mode="All",Data!I33=Sel_Mode),OR(Sel_Gender="All",D33=Sel_Gender),OR(Sel_Category="All",Data!B33=Sel_Category),OR(Sel_Month="All",C33=Sel_Month),OR(Sel_County="All",Data!L33=Sel_County)),1,0) -> 1 | R33: Placer County
A34: =Data!A34 -> TX500033 | B34: =MONTH(Data!F34) -> 1 | C34: =TEXT(Data!F34,"mmm") -> Jan | D34: =Data!O34 -> Male | E34: =Data!G34-Data!F34 -> 1 | F34: =IF(Data!J34<=5,Data!J34,IF(Data!J34<=10,"6 TO 10","More than 10")) -> 4 | G34: =IF(E34>=8,"8+",E34) -> 1 | H34: =ROUND(Data!C34*Data!D34-Data!E34,2) -> 0 | I34: =IF(AND(OR(Sel_Mode="All",Data!I34=Sel_Mode),OR(Sel_Gender="All",D34=Sel_Gender),OR(Sel_Category="All",Data!B34=Sel_Category),OR(Sel_Month="All",C34=Sel_Month),OR(Sel_County="All",Data!L34=Sel_County)),1,0) -> 1 | R34: Plumas County
... A60: =Data!A60 -> TX500059 | B60: =MONTH(Data!F60) -> 1 | C60: =TEXT(Data!F60,"mmm") -> Jan | D60: =Data!O60 -> Male | E60: =Data!G60-Data!F60 -> 1 | F60: =IF(Data!J60<=5,Data!J60,IF(Data!J60<=10,"6 TO 10","More than 10")) -> 5 | G60: =IF(E60>=8,"8+",E60) -> 1 | H60: =ROUND(Data!C60*Data!D60-Data!E60,2) -> 0 | I60: =IF(AND(OR(Sel_Mode="All",Data!I60=Sel_Mode),OR(Sel_Gender="All",D60=Sel_Gender),OR(Sel_Category="All",Data!B60=Sel_Category),OR(Sel_Month="All",C60=Sel_Month),OR(Sel_County="All",Data!L60=Sel_County)),1,0) -> 1 | R60: Yuba County
A61: =Data!A61 -> TX500060 | B61: =MONTH(Data!F61) -> 1 | C61: =TEXT(Data!F61,"mmm") -> Jan | D61: =Data!O61 -> Female | E61: =Data!G61-Data!F61 -> 3 | F61: =IF(Data!J61<=5,Data!J61,IF(Data!J61<=10,"6 TO 10","More than 10")) -> 5 | G61: =IF(E61>=8,"8+",E61) -> 3 | H61: =ROUND(Data!C61*Data!D61-Data!E61,2) -> 0 | I61: =IF(AND(OR(Sel_Mode="All",Data!I61=Sel_Mode),OR(Sel_Gender="All",D61=Sel_Gender),OR(Sel_Category="All",Data!B61=Sel_Category),OR(Sel_Month="All",C61=Sel_Month),OR(Sel_County="All",Data!L61=Sel_County)),1,0) -> 1
A62: =Data!A62 -> TX500061 | B62: =MONTH(Data!F62) -> 1 | C62: =TEXT(Data!F62,"mmm") -> Jan | D62: =Data!O62 -> Female | E62: =Data!G62-Data!F62 -> 2 | F62: =IF(Data!J62<=5,Data!J62,IF(Data!J62<=10,"6 TO 10","More than 10")) -> 3 | G62: =IF(E62>=8,"8+",E62) -> 2 | H62: =ROUND(Data!C62*Data!D62-Data!E62,2) -> 0 | I62: =IF(AND(OR(Sel_Mode="All",Data!I62=Sel_Mode),OR(Sel_Gender="All",D62=Sel_Gender),OR(Sel_Category="All",Data!B62=Sel_Category),OR(Sel_Month="All",C62=Sel_Month),OR(Sel_County="All",Data!L62=Sel_County)),1,0) -> 1 | N62: Blue text = typed values that feed the dashboard dropdowns (equivalent to =UNIQUE(...) in Excel 365).
A63: =Data!A63 -> TX500062 | B63: =MONTH(Data!F63) -> 1 | C63: =TEXT(Data!F63,"mmm") -> Jan | D63: =Data!O63 -> Female | E63: =Data!G63-Data!F63 -> 1 | F63: =IF(Data!J63<=5,Data!J63,IF(Data!J63<=10,"6 TO 10","More than 10")) -> 4 | G63: =IF(E63>=8,"8+",E63) -> 1 | H63: =ROUND(Data!C63*Data!D63-Data!E63,2) -> 0 | I63: =IF(AND(OR(Sel_Mode="All",Data!I63=Sel_Mode),OR(Sel_Gender="All",D63=Sel_Gender),OR(Sel_Category="All",Data!B63=Sel_Category),OR(Sel_Month="All",C63=Sel_Month),OR(Sel_County="All",Data!L63=Sel_County)),1,0) -> 1
A64: =Data!A64 -> TX500063 | B64: =MONTH(Data!F64) -> 1 | C64: =TEXT(Data!F64,"mmm") -> Jan | D64: =Data!O64 -> Female | E64: =Data!G64-Data!F64 -> 5 | F64: =IF(Data!J64<=5,Data!J64,IF(Data!J64<=10,"6 TO 10","More than 10")) -> 4 | G64: =IF(E64>=8,"8+",E64) -> 5 | H64: =ROUND(Data!C64*Data!D64-Data!E64,2) -> 0 | I64: =IF(AND(OR(Sel_Mode="All",Data!I64=Sel_Mode),OR(Sel_Gender="All",D64=Sel_Gender),OR(Sel_Category="All",Data!B64=Sel_Category),OR(Sel_Month="All",C64=Sel_Month),OR(Sel_County="All",Data!L64=Sel_County)),1,0) -> 1
A65: =Data!A65 -> TX500064 | B65: =MONTH(Data!F65) -> 1 | C65: =TEXT(Data!F65,"mmm") -> Jan | D65: =Data!O65 -> Male | E65: =Data!G65-Data!F65 -> 1 | F65: =IF(Data!J65<=5,Data!J65,IF(Data!J65<=10,"6 TO 10","More than 10")) -> 2 | G65: =IF(E65>=8,"8+",E65) -> 1 | H65: =ROUND(Data!C65*Data!D65-Data!E65,2) -> 0 | I65: =IF(AND(OR(Sel_Mode="All",Data!I65=Sel_Mode),OR(Sel_Gender="All",D65=Sel_Gender),OR(Sel_Category="All",Data!B65=Sel_Category),OR(Sel_Month="All",C65=Sel_Month),OR(Sel_County="All",Data!L65=Sel_County)),1,0) -> 1
...

Sheet Data
A1: TX ID | B1: Product | C1: Quantity | D1: Unit Price | E1: Amount | F1: Order Date | G1: Ship Date | H1: Customer Gender | I1: Order Mode | J1: Rating C | K1: State | L1: County | M1: Days to Deliver | N1: Weeknum | O1: Gender Value
A2: TX500001 | B2: Shorts | C2: 1 | D2: 10.9 | E2: 10.9 | F2: 45658 | G2: 45663 | I2: App | J2: 4 | K2: California | L2: Alpine County | M2: =orders[[#This Row],[Ship Date]]-orders[[#This Row],[Order Date]] -> 5 | N2: =WEEKNUM(orders[[#This Row],[Order Date]],1) -> 1 | O2: {=_xlfn.IFS(orders[[#This Row],[Customer Gender]]="M","Male", orders[[#This Row],[Customer Gender]]="F","Female", orders[[#This Row],[Customer Gender]]="O","Other", TRUE(),"Unknown")} -> Unknown
A3: TX500002 | B3: Tank Tops | C3: 2 | D3: 30.6 | E3: 61.2 | F3: 45658 | G3: 45660 | H3: M | I3: App | J3: 4 | K3: California | L3: Contra Costa County | M3: =orders[[#This Row],[Ship Date]]-orders[[#This Row],[Order Date]] -> 2 | N3: =WEEKNUM(orders[[#This Row],[Order Date]],1) -> 1 | O3: {=_xlfn.IFS(orders[[#This Row],[Customer Gender]]="M","Male", orders[[#This Row],[Customer Gender]]="F","Female", orders[[#This Row],[Customer Gender]]="O","Other", TRUE(),"Unknown")} -> Male
A4: TX500003 | B4: Sneakers | C4: 3 | D4: 109.4 | E4: 328.2 | F4: 45658 | G4: 45661 | H4: F | I4: App | J4: 3 | K4: California | L4: Fresno County | M4: =orders[[#This Row],[Ship Date]]-orders[[#This Row],[Order Date]] -> 3 | N4: =WEEKNUM(orders[[#This Row],[Order Date]],1) -> 1 | O4: {=_xlfn.IFS(orders[[#This Row],[Customer Gender]]="M","Male", orders[[#This Row],[Customer Gender]]="F","Female", orders[[#This Row],[Customer Gender]]="O","Other", TRUE(),"Unknown")} -> Female
A5: TX500004 | B5: Workout Tops | C5: 7 | D5: 37.7 | E5: 263.9 | F5: 45658 | G5: 45659 | H5: F | I5: App | J5: 4 | K5: California | L5: Fresno County | M5: =orders[[#This Row],[Ship Date]]-orders[[#This Row],[Order Date]] -> 1 | N5: =WEEKNUM(orders[[#This Row],[Order Date]],1) -> 1 | O5: {=_xlfn.IFS(orders[[#This Row],[Customer Gender]]="M","Male", orders[[#This Row],[Customer Gender]]="F","Female", orders[[#This Row],[Customer Gender]]="O","Other", TRUE(),"Unknown")} -> Female
A6: TX500005 | B6: Graphic Tees | C6: 3 | D6: 56.7 | E6: 170.1 | F6: 45658 | G6: 45661 | H6: F | I6: App | J6: 5 | K6: California | L6: Los Angeles County | M6: =orders[[#This Row],[Ship Date]]-orders[[#This Row],[Order Date]] -> 3 | N6: =WEEKNUM(orders[[#This Row],[Order Date]],1) -> 1 | O6: {=_xlfn.IFS(orders[[#This Row],[Customer Gender]]="M","Male", orders[[#This Row],[Customer Gender]]="F","Female", orders[[#This Row],[Customer Gender]]="O","Other", TRUE(),"Unknown")} -> Female
A7: TX500006 | B7: Tank Tops | C7: 12 | D7: 83.5 | E7: 1002 | F7: 45658 | G7: 45661 | H7: M | I7: Website | J7: 4 | K7: California | L7: Los Angeles County | M7: =orders[[#This Row],[Ship Date]]-orders[[#This Row],[Order Date]] -> 3 | N7: =WEEKNUM(orders[[#This Row],[Order Date]],1) -> 1 | O7: {=_xlfn.IFS(orders[[#This Row],[Customer Gender]]="M","Male", orders[[#This Row],[Customer Gender]]="F","Female", orders[[#This Row],[Customer Gender]]="O","Other", TRUE(),"Unknown")} -> Male
A8: TX500007 | B8: Sandals | C8: 1 | D8: 55.3 | E8: 55.3 | F8: 45658 | G8: 45659 | H8: F | I8: App | J8: 4 | K8: California | L8: Los Angeles County | M8: =orders[[#This Row],[Ship Date]]-orders[[#This Row],[Order Date]] -> 1 | N8: =WEEKNUM(orders[[#This Row],[Order Date]],1) -> 1 | O8: {=_xlfn.IFS(orders[[#This Row],[Customer Gender]]="M","Male", orders[[#This Row],[Customer Gender]]="F","Female", orders[[#This Row],[Customer Gender]]="O","Other", TRUE(),"Unknown")} -> Female
A9: TX500008 | B9: Jeans | C9: 2 | D9: 40.3 | E9: 80.6 | F9: 45658 | G9: 45659 | H9: M | I9: Target.com | J9: 5 | K9: California | L9: Los Angeles County | M9: =orders[[#This Row],[Ship Date]]-orders[[#This Row],[Order Date]] -> 1 | N9: =WEEKNUM(orders[[#This Row],[Order Date]],1) -> 1 | O9: {=_xlfn.IFS(orders[[#This Row],[Customer Gender]]="M","Male", orders[[#This Row],[Customer Gender]]="F","Female", orders[[#This Row],[Customer Gender]]="O","Other", TRUE(),"Unknown")} -> Male
A10: TX500009 | B10: Hoodies & Sweatshirts | C10: 11 | D10: 35.7 | E10: 392.7 | F10: 45658 | G10: 45659 | H10: F | I10: App | J10: 4 | K10: California | L10: Los Angeles County | M10: =orders[[#This Row],[Ship Date]]-orders[[#This Row],[Order Date]] -> 1 | N10: =WEEKNUM(orders[[#This Row],[Order Date]],1) -> 1 | O10: {=_xlfn.IFS(orders[[#This Row],[Customer Gender]]="M","Male", orders[[#This Row],[Customer Gender]]="F","Female", orders[[#This Row],[Customer Gender]]="O","Other", TRUE(),"Unknown")} -> Female
A11: TX500010 | B11: T-Shirts | C11: 7 | D11: 22.4 | E11: 156.8 | F11: 45658 | G11: 45661 | H11: M | I11: App | J11: 3 | K11: California | L11: Los Angeles County | M11: =orders[[#This Row],[Ship Date]]-orders[[#This Row],[Order Date]] -> 3 | N11: =WEEKNUM(orders[[#This Row],[Order Date]],1) -> 1 | O11: {=_xlfn.IFS(orders[[#This Row],[Customer Gender]]="M","Male", orders[[#This Row],[Customer Gender]]="F","Female", orders[[#This Row],[Customer Gender]]="O","Other", TRUE(),"Unknown")} -> Male
A12: TX500011 | B12: Sundresses | C12: 2 | D12: 54.4 | E12: 108.8 | F12: 45658 | G12: 45664 | H12: F | I12: App | J12: 4 | K12: California | L12: Los Angeles County | M12: =orders[[#This Row],[Ship Date]]-orders[[#This Row],[Order Date]] -> 6 | N12: =WEEKNUM(orders[[#This Row],[Order Date]],1) -> 1 | O12: {=_xlfn.IFS(orders[[#This Row],[Customer Gender]]="M","Male", orders[[#This Row],[Customer Gender]]="F","Female", orders[[#This Row],[Customer Gender]]="O","Other", TRUE(),"Unknown")} -> Female
A13: TX500012 | B13: Sundresses | C13: 2 | D13: 49 | E13: 98 | F13: 45658 | G13: 45660 | H13: F | I13: Target.com | J13: 3 | K13: California | L13: Los Angeles County | M13: =orders[[#This Row],[Ship Date]]-orders[[#This Row],[Order Date]] -> 2 | N13: =WEEKNUM(orders[[#This Row],[Order Date]],1) -> 1 | O13: {=_xlfn.IFS(orders[[#This Row],[Customer Gender]]="M","Male", orders[[#This Row],[Customer Gender]]="F","Female", orders[[#This Row],[Customer Gender]]="O","Other", TRUE(),"Unknown")} -> Female
A14: TX500013 | B14: Sandals | C14: 7 | D14: 118.6 | E14: 830.2 | F14: 45658 | G14: 45662 | H14: F | I14: Website | J14: 4 | K14: California | L14: Nevada County | M14: =orders[[#This Row],[Ship Date]]-orders[[#This Row],[Order Date]] -> 4 | N14: =WEEKNUM(orders[[#This Row],[Order Date]],1) -> 1 | O14: {=_xlfn.IFS(orders[[#This Row],[Customer Gender]]="M","Male", orders[[#This Row],[Customer Gender]]="F","Female", orders[[#This Row],[Customer Gender]]="O","Other", TRUE(),"Unknown")} -> Female
... A28: TX500027 | B28: Tank Tops | C28: 9 | D28: 38.7 | E28: 348.3 | F28: 45658 | G28: 45661 | H28: M | I28: Website | J28: 4 | K28: California | L28: Santa Barbara County | M28: =orders[[#This Row],[Ship Date]]-orders[[#This Row],[Order Date]] -> 3 | N28: =WEEKNUM(orders[[#This Row],[Order Date]],1) -> 1 | O28: {=_xlfn.IFS(orders[[#This Row],[Customer Gender]]="M","Male", orders[[#This Row],[Customer Gender]]="F","Female", orders[[#This Row],[Customer Gender]]="O","Other", TRUE(),"Unknown")} -> Male
A29: TX500028 | B29: Tote Bags | C29: 4 | D29: 57.2 | E29: 228.8 | F29: 45658 | G29: 45660 | I29: Website | J29: 5 | K29: California | L29: Santa Clara County | M29: =orders[[#This Row],[Ship Date]]-orders[[#This Row],[Order Date]] -> 2 | N29: =WEEKNUM(orders[[#This Row],[Order Date]],1) -> 1 | O29: {=_xlfn.IFS(orders[[#This Row],[Customer Gender]]="M","Male", orders[[#This Row],[Customer Gender]]="F","Female", orders[[#This Row],[Customer Gender]]="O","Other", TRUE(),"Unknown")} -> Unknown
A30: TX500029 | B30: Jeans | C30: 5 | D30: 50.9 | E30: 254.5 | F30: 45658 | G30: 45664 | I30: Website | J30: 5 | K30: California | L30: Tehama County | M30: =orders[[#This Row],[Ship Date]]-orders[[#This Row],[Order Date]] -> 6 | N30: =WEEKNUM(orders[[#This Row],[Order Date]],1) -> 1 | O30: {=_xlfn.IFS(orders[[#This Row],[Customer Gender]]="M","Male", orders[[#This Row],[Customer Gender]]="F","Female", orders[[#This Row],[Customer Gender]]="O","Other", TRUE(),"Unknown")} -> Unknown
A31: TX500030 | B31: Baseball Caps | C31: 7 | D31: 41 | E31: 287 | F31: 45658 | G31: 45662 | H31: F | I31: Website | J31: 4 | K31: California | L31: Ventura County | M31: =orders[[#This Row],[Ship Date]]-orders[[#This Row],[Order Date]] -> 4 | N31: =WEEKNUM(orders[[#This Row],[Order Date]],1) -> 1 | O31: {=_xlfn.IFS(orders[[#This Row],[Customer Gender]]="M","Male", orders[[#This Row],[Customer Gender]]="F","Female", orders[[#This Row],[Customer Gender]]="O","Other", TRUE(),"Unknown")} -> Female
A32: TX500031 | B32: T-Shirts | C32: 7 | D32: 19.1 | E32: 133.7 | F32: 45658 | G32: 45662 | H32: M | I32: App | J32: 5 | K32: California | L32: Calaveras County | M32: =orders[[#This Row],[Ship Date]]-orders[[#This Row],[Order Date]] -> 4 | N32: =WEEKNUM(orders[[#This Row],[Order Date]],1) -> 1 | O32: {=_xlfn.IFS(orders[[#This Row],[Customer Gender]]="M","Male", orders[[#This Row],[Customer Gender]]="F","Female", orders[[#This Row],[Customer Gender]]="O","Other", TRUE(),"Unknown")} -> Male
A33: TX500032 | B33: Sneakers | C33: 5 | D33: 166.1 | E33: 830.5 | F33: 45658 | G33: 45661 | H33: M | I33: App | J33: 4 | K33: California | L33: Inyo County | M33: =orders[[#This Row],[Ship Date]]-orders[[#This Row],[Order Date]] -> 3 | N33: =WEEKNUM(orders[[#This Row],[Order Date]],1) -> 1 | O33: {=_xlfn.IFS(orders[[#This Row],[Customer Gender]]="M","Male", orders[[#This Row],[Customer Gender]]="F","Female", orders[[#This Row],[Customer Gender]]="O","Other", TRUE(),"Unknown")} -> Male
A34: TX500033 | B34: Graphic Tees | C34: 3 | D34: 29.9 | E34: 89.7 | F34: 45658 | G34: 45659 | H34: M | I34: Instagram | J34: 4 | K34: California | L34: Los Angeles County | M34: =orders[[#This Row],[Ship Date]]-orders[[#This Row],[Order Date]] -> 1 | N34: =WEEKNUM(orders[[#This Row],[Order Date]],1) -> 1 | O34: {=_xlfn.IFS(orders[[#This Row],[Customer Gender]]="M","Male", orders[[#This Row],[Customer Gender]]="F","Female", orders[[#This Row],[Customer Gender]]="O","Other", TRUE(),"Unknown")} -> Male
A35: TX500034 | B35: Bikinis | C35: 6 | D35: 21.7 | E35: 130.2 | F35: 45658 | G35: 45660 | H35: O | I35: Target.com | J35: 5 | K35: California | L35: Los Angeles County | M35: =orders[[#This Row],[Ship Date]]-orders[[#This Row],[Order Date]] -> 2 | N35: =WEEKNUM(orders[[#This Row],[Order Date]],1) -> 1 | O35: {=_xlfn.IFS(orders[[#This Row],[Customer Gender]]="M","Male", orders[[#This Row],[Customer Gender]]="F","Female", orders[[#This Row],[Customer Gender]]="O","Other", TRUE(),"Unknown")} -> Other
A36: TX500035 | B36: Maxi Dresses | C36: 2 | D36: 32 | E36: 64 | F36: 45658 | G36: 45661 | H36: M | I36: App | J36: 5 | K36: California | L36: Los Angeles County | M36: =orders[[#This Row],[Ship Date]]-orders[[#This Row],[Order Date]] -> 3 | N36: =WEEKNUM(orders[[#This Row],[Order Date]],1) -> 1 | O36: {=_xlfn.IFS(orders[[#This Row],[Customer Gender]]="M","Male", orders[[#This Row],[Customer Gender]]="F","Female", orders[[#This Row],[Customer Gender]]="O","Other", TRUE(),"Unknown")} -> Male
A37: TX500036 | B37: T-Shirts | C37: 2 | D37: 15.8 | E37: 31.6 | F37: 45658 | G37: 45659 | H37: M | I37: Partner App | J37: 5 | K37: California | L37: Los Angeles County | M37: =orders[[#This Row],[Ship Date]]-orders[[#This Row],[Order Date]] -> 1 | N37: =WEEKNUM(orders[[#This Row],[Order Date]],1) -> 1 | O37: {=_xlfn.IFS(orders[[#This Row],[Customer Gender]]="M","Male", orders[[#This Row],[Customer Gender]]="F","Female", orders[[#This Row],[Customer Gender]]="O","Other", TRUE(),"Unknown")} -> Male
A38: TX500037 | B38: Sneakers | C38: 17 | D38: 203.1 | E38: 3452.7 | F38: 45658 | G38: 45662 | H38: M | I38: Instagram | J38: 3 | K38: California | L38: Los Angeles County | M38: =orders[[#This Row],[Ship Date]]-orders[[#This Row],[Order Date]] -> 4 | N38: =WEEKNUM(orders[[#This Row],[Order Date]],1) -> 1 | O38: {=_xlfn.IFS(orders[[#This Row],[Customer Gender]]="M","Male", orders[[#This Row],[Customer Gender]]="F","Female", orders[[#This Row],[Customer Gender]]="O","Other", TRUE(),"Unknown")} -> Male
A39: TX500038 | B39: Hoodies & Sweatshirts | C39: 13 | D39: 39 | E39: 507 | F39: 45658 | G39: 45664 | H39: M | I39: App | J39: 5 | K39: California | L39: Los Angeles County | M39: =orders[[#This Row],[Ship Date]]-orders[[#This Row],[Order Date]] -> 6 | N39: =WEEKNUM(orders[[#This Row],[Order Date]],1) -> 1 | O39: {=_xlfn.IFS(orders[[#This Row],[Customer Gender]]="M","Male", orders[[#This Row],[Customer Gender]]="F","Female", orders[[#This Row],[Customer Gender]]="O","Other", TRUE(),"Unknown")} -> Male
A40: TX500039 | B40: Bikinis | C40: 1 | D40: 26.5 | E40: 26.5 | F40: 45659 | G40: 45660 | H40: M | I40: Target.com | J40: 4 | K40: California | L40: Los Angeles County | M40: =orders[[#This Row],[Ship Date]]-orders[[#This Row],[Order Date]] -> 1 | N40: =WEEKNUM(orders[[#This Row],[Order Date]],1) -> 1 | O40: {=_xlfn.IFS(orders[[#This Row],[Customer Gender]]="M","Male", orders[[#This Row],[Customer Gender]]="F","Female", orders[[#This Row],[Customer Gender]]="O","Other", TRUE(),"Unknown")} -> Male
A41: TX500040 | B41: Sandals | C41: 1 | D41: 43.1 | E41: 43.1 | F41: 45659 | G41: 45660 | H41: F | I41: Target.com | J41: 3 | K41: California | L41: Los Angeles County | M41: =orders[[#This Row],[Ship Date]]-orders[[#This Row],[Order Date]] -> 1 | N41: =WEEKNUM(orders[[#This Row],[Order Date]],1) -> 1 | O41: {=_xlfn.IFS(orders[[#This Row],[Customer Gender]]="M","Male", orders[[#This Row],[Customer Gender]]="F","Female", orders[[#This Row],[Customer Gender]]="O","Other", TRUE(),"Unknown")} -> Female
A42: TX500041 | B42: Tank Tops | C42: 3 | D42: 139 | E42: 417 | F42: 45659 | G42: 45660 | H42: F | I42: Partner App | J42: 5 | K42: California | L42: Los Angeles County | M42: =orders[[#This Row],[Ship Date]]-orders[[#This Row],[Order Date]] -> 1 | N42: =WEEKNUM(orders[[#This Row],[Order Date]],1) -> 1 | O42: {=_xlfn.IFS(orders[[#This Row],[Customer Gender]]="M","Male", orders[[#This Row],[Customer Gender]]="F","Female", orders[[#This Row],[Customer Gender]]="O","Other", TRUE(),"Unknown")} -> Female
... A91: TX500090 | B91: Sneakers | C91: 1 | D91: 97.7 | E91: 97.7 | F91: 45661 | G91: 45664 | H91: F | I91: Website | J91: 4 | K91: California | L91: Los Angeles County | M91: =orders[[#This Row],[Ship Date]]-orders[[#This Row],[Order Date]] -> 3 | N91: =WEEKNUM(orders[[#This Row],[Order Date]],1) -> 1 | O91: {=_xlfn.IFS(orders[[#This Row],[Customer Gender]]="M","Male", orders[[#This Row],[Customer Gender]]="F","Female", orders[[#This Row],[Customer Gender]]="O","Other", TRUE(),"Unknown")} -> Female
A92: TX500091 | B92: Sundresses | C92: 5 | D92: 54.7 | E92: 273.5 | F92: 45661 | G92: 45664 | I92: App | J92: 5 | K92: California | L92: Riverside County | M92: =orders[[#This Row],[Ship Date]]-orders[[#This Row],[Order Date]] -> 3 | N92: =WEEKNUM(orders[[#This Row],[Order Date]],1) -> 1 | O92: {=_xlfn.IFS(orders[[#This Row],[Customer Gender]]="M","Male", orders[[#This Row],[Customer Gender]]="F","Female", orders[[#This Row],[Customer Gender]]="O","Other", TRUE(),"Unknown")} -> Unknown
A93: TX500092 | B93: Sneakers | C93: 6 | D93: 130.5 | E93: 783 | F93: 45661 | G93: 45663 | H93: F | I93: App | J93: 3 | K93: California | L93: Riverside County | M93: =orders[[#This Row],[Ship Date]]-orders[[#This Row],[Order Date]] -> 2 | N93: =WEEKNUM(orders[[#This Row],[Order Date]],1) -> 1 | O93: {=_xlfn.IFS(orders[[#This Row],[Customer Gender]]="M","Male", orders[[#This Row],[Customer Gender]]="F","Female", orders[[#This Row],[Customer Gender]]="O","Other", TRUE(),"Unknown")} -> Female
A94: TX500093 | B94: Maxi Dresses | C94: 2 | D94: 50.4 | E94: 100.8 | F94: 45661 | G94: 45663 | H94: M | I94: Target.com | J94: 5 | K94: California | L94: Sacramento County | M94: =orders[[#This Row],[Ship Date]]-orders[[#This Row],[Order Date]] -> 2 | N94: =WEEKNUM(orders[[#This Row],[Order Date]],1) -> 1 | O94: {=_xlfn.IFS(orders[[#This Row],[Customer Gender]]="M","Male", orders[[#This Row],[Customer Gender]]="F","Female", orders[[#This Row],[Customer Gender]]="O","Other", TRUE(),"Unknown")} -> Male
A95: TX500094 | B95: Jeans | C95: 13 | D95: 61.5 | E95: 799.5 | F95: 45661 | G95: 45662 | I95: Instagram | J95: 3 | K95: California | L95: Santa Clara County | M95: =orders[[#This Row],[Ship Date]]-orders[[#This Row],[Order Date]] -> 1 | N95: =WEEKNUM(orders[[#This Row],[Order Date]],1) -> 1 | O95: {=_xlfn.IFS(orders[[#This Row],[Customer Gender]]="M","Male", orders[[#This Row],[Customer Gender]]="F","Female", orders[[#This Row],[Customer Gender]]="O","Other", TRUE(),"Unknown")} -> Unknown
A96: TX500095 | B96: Sundresses | C96: 4 | D96: 30.1 | E96: 120.4 | F96: 45661 | G96: 45662 | H96: F | I96: App | J96: 5 | K96: California | L96: Alameda County | M96: =orders[[#This Row],[Ship Date]]-orders[[#This Row],[Order Date]] -> 1 | N96: =WEEKNUM(orders[[#This Row],[Order Date]],1) -> 1 | O96: {=_xlfn.IFS(orders[[#This Row],[Customer Gender]]="M","Male", orders[[#This Row],[Customer Gender]]="F","Female", orders[[#This Row],[Customer Gender]]="O","Other", TRUE(),"Unknown")} -> Female
A97: TX500096 | B97: Sneakers | C97: 5 | D97: 74.8 | E97: 374 | F97: 45661 | G97: 45662 | H97: F | I97: Website | J97: 4 | K97: California | L97: Contra Costa County | M97: =orders[[#This Row],[Ship Date]]-orders[[#This Row],[Order Date]] -> 1 | N97: =WEEKNUM(orders[[#This Row],[Order Date]],1) -> 1 | O97: {=_xlfn.IFS(orders[[#This Row],[Customer Gender]]="M","Male", orders[[#This Row],[Customer Gender]]="F","Female", orders[[#This Row],[Customer Gender]]="O","Other", TRUE(),"Unknown")} -> Female
A98: TX500097 | B98: Sunglasses | C98: 3 | D98: 64.9 | E98: 194.7 | F98: 45661 | G98: 45668 | H98: M | I98: App | J98: 4 | K98: California | L98: Fresno County | M98: =orders[[#This Row],[Ship Date]]-orders[[#This Row],[Order Date]] -> 7 | N98: =WEEKNUM(orders[[#This Row],[Order Date]],1) -> 1 | O98: {=_xlfn.IFS(orders[[#This Row],[Customer Gender]]="M","Male", orders[[#This Row],[Customer Gender]]="F","Female", orders[[#This Row],[Customer Gender]]="O","Other", TRUE(),"Unknown")} -> Male
A99: TX500098 | B99: Sundresses | C99: 2 | D99: 50.5 | E99: 101 | F99: 45661 | G99: 45663 | H99: M | I99: Website | J99: 4 | K99: California | L99: Kern County | M99: =orders[[#This Row],[Ship Date]]-orders[[#This Row],[Order Date]] -> 2 | N99: =WEEKNUM(orders[[#This Row],[Order Date]],1) -> 1 | O99: {=_xlfn.IFS(orders[[#This Row],[Customer Gender]]="M","Male", orders[[#This Row],[Customer Gender]]="F","Female", orders[[#This Row],[Customer Gender]]="O","Other", TRUE(),"Unknown")} -> Male
A100: TX500099 | B100: Maxi Dresses | C100: 7 | D100: 63 | E100: 441 | F100: 45661 | G100: 45664 | H100: M | I100: Instagram | J100: 5 | K100: California | L100: Los Angeles County | M100: =orders[[#This Row],[Ship Date]]-orders[[#This Row],[Order Date]] -> 3 | N100: =WEEKNUM(orders[[#This Row],[Order Date]],1) -> 1 | O100: {=_xlfn.IFS(orders[[#This Row],[Customer Gender]]="M","Male", orders[[#This Row],[Customer Gender]]="F","Female", orders[[#This Row],[Customer Gender]]="O","Other", TRUE(),"Unknown")} -> Male
A101: TX500100 | B101: Sneakers | C101: 3 | D101: 93.6 | E101: 280.8 | F101: 45661 | G101: 45674 | H101: F | I101: App | J101: 5 | K101: California | L101: Los Angeles County | M101: =orders[[#This Row],[Ship Date]]-orders[[#This Row],[Order Date]] -> 13 | N101: =WEEKNUM(orders[[#This Row],[Order Date]],1) -> 1 | O101: {=_xlfn.IFS(orders[[#This Row],[Customer Gender]]="M","Male", orders[[#This Row],[Customer Gender]]="F","Female", orders[[#This Row],[Customer Gender]]="O","Other", TRUE(),"Unknown")} -> Female
...

Sheet Questions & KPIs
B2: KPIs
B3: Total Orders
B4: Total Quantity
B5: Total Amount
B6: Avg. Rating
B7: Avg. Days to Deliver
B10: Questions
B11: Trend in the last 13 weeks
B12: How our customers like to buy
B13: How many they buy?
B14: Which products are popular?
B15: Overall gender split
... B18: How happy are our customers?
